<?xml version="1.0" encoding="UTF-8"?>
<sdf version="1.9">
  <world name="default">
    <physics type="ode">
      <max_step_size>0.004</max_step_size>
      <real_time_factor>1.0</real_time_factor>
      <real_time_update_rate>250</real_time_update_rate>
    </physics>
    <plugin name="gz::sim::systems::Physics" filename="gz-sim-physics-system"/>
    <plugin name="gz::sim::systems::UserCommands" filename="gz-sim-user-commands-system"/>
    <plugin name="gz::sim::systems::SceneBroadcaster" filename="gz-sim-scene-broadcaster-system"/>
    <plugin name="gz::sim::systems::Contact" filename="gz-sim-contact-system"/>
    <plugin name="gz::sim::systems::Imu" filename="gz-sim-imu-system"/>
    <plugin name="gz::sim::systems::AirPressure" filename="gz-sim-air-pressure-system"/>
    <plugin name="gz::sim::systems::ApplyLinkWrench" filename="gz-sim-apply-link-wrench-system"/>
    <plugin name="gz::sim::systems::NavSat" filename="gz-sim-navsat-system"/>
    <plugin name="gz::sim::systems::Sensors" filename="gz-sim-sensors-system">
      <render_engine>ogre2</render_engine>
    </plugin>
    <gui fullscreen="false">
      <!-- 3D scene -->
      <plugin filename="MinimalScene" name="3D View">
        <gz-gui>
          <title>3D View</title>
          <property type="bool" key="showTitleBar">false</property>
          <property type="string" key="state">docked</property>
        </gz-gui>
        <engine>ogre2</engine>
        <scene>scene</scene>
        <ambient_light>0.4 0.4 0.4</ambient_light>
        <background_color>0.8 0.8 0.8</background_color>
        <camera_pose>-6 0 6 0 0.5 0</camera_pose>
        <camera_clip>
          <near>0.25</near>
          <far>25000</far>
        </camera_clip>
      </plugin>
      <!-- Plugins that add functionality to the scene -->
      <plugin filename="EntityContextMenuPlugin" name="Entity context menu">
        <gz-gui>
          <property key="state" type="string">floating</property>
          <property key="width" type="double">5</property>
          <property key="height" type="double">5</property>
          <property key="showTitleBar" type="bool">false</property>
        </gz-gui>
      </plugin>
      <plugin filename="GzSceneManager" name="Scene Manager">
        <gz-gui>
          <property key="resizable" type="bool">false</property>
          <property key="width" type="double">5</property>
          <property key="height" type="double">5</property>
          <property key="state" type="string">floating</property>
          <property key="showTitleBar" type="bool">false</property>
        </gz-gui>
      </plugin>
      <plugin filename="InteractiveViewControl" name="Interactive view control">
        <gz-gui>
          <property key="resizable" type="bool">false</property>
          <property key="width" type="double">5</property>
          <property key="height" type="double">5</property>
          <property key="state" type="string">floating</property>
          <property key="showTitleBar" type="bool">false</property>
        </gz-gui>
      </plugin>
      <plugin filename="CameraTracking" name="Camera Tracking">
        <gz-gui>
          <property key="resizable" type="bool">false</property>
          <property key="width" type="double">5</property>
          <property key="height" type="double">5</property>
          <property key="state" type="string">floating</property>
          <property key="showTitleBar" type="bool">false</property>
        </gz-gui>
      </plugin>
      <plugin filename="MarkerManager" name="Marker manager">
        <gz-gui>
          <property key="resizable" type="bool">false</property>
          <property key="width" type="double">5</property>
          <property key="height" type="double">5</property>
          <property key="state" type="string">floating</property>
          <property key="showTitleBar" type="bool">false</property>
        </gz-gui>
      </plugin>
      <plugin filename="SelectEntities" name="Select Entities">
        <gz-gui>
          <anchors target="Select entities">
            <line own="right" target="right"/>
            <line own="top" target="top"/>
          </anchors>
          <property key="resizable" type="bool">false</property>
          <property key="width" type="double">5</property>
          <property key="height" type="double">5</property>
          <property key="state" type="string">floating</property>
          <property key="showTitleBar" type="bool">false</property>
        </gz-gui>
      </plugin>
      <plugin filename="VisualizationCapabilities" name="Visualization Capabilities">
        <gz-gui>
          <property key="resizable" type="bool">false</property>
          <property key="width" type="double">5</property>
          <property key="height" type="double">5</property>
          <property key="state" type="string">floating</property>
          <property key="showTitleBar" type="bool">false</property>
        </gz-gui>
      </plugin>
      <plugin filename="Spawn" name="Spawn Entities">
        <gz-gui>
          <anchors target="Select entities">
            <line own="right" target="right"/>
            <line own="top" target="top"/>
          </anchors>
          <property key="resizable" type="bool">false</property>
          <property key="width" type="double">5</property>
          <property key="height" type="double">5</property>
          <property key="state" type="string">floating</property>
          <property key="showTitleBar" type="bool">false</property>
        </gz-gui>
      </plugin>
      <plugin name="World control" filename="WorldControl">
        <gz-gui>
          <title>World control</title>
          <property type="bool" key="showTitleBar">0</property>
          <property type="bool" key="resizable">0</property>
          <property type="double" key="height">72</property>
          <property type="double" key="width">121</property>
          <property type="double" key="z">1</property>
          <property type="string" key="state">floating</property>
          <anchors target="3D View">
            <line own="left" target="left"/>
            <line own="bottom" target="bottom"/>
          </anchors>
        </gz-gui>
        <play_pause>1</play_pause>
        <step>1</step>
        <start_paused>1</start_paused>
      </plugin>
      <plugin name="World stats" filename="WorldStats">
        <gz-gui>
          <title>World stats</title>
          <property type="bool" key="showTitleBar">0</property>
          <property type="bool" key="resizable">0</property>
          <property type="double" key="height">110</property>
          <property type="double" key="width">290</property>
          <property type="double" key="z">1</property>
          <property type="string" key="state">floating</property>
          <anchors target="3D View">
            <line own="right" target="right"/>
            <line own="bottom" target="bottom"/>
          </anchors>
        </gz-gui>
        <sim_time>1</sim_time>
        <real_time>1</real_time>
        <real_time_factor>1</real_time_factor>
        <iterations>1</iterations>
      </plugin>
      <plugin name="Entity tree" filename="EntityTree"/>
    </gui>
    <gravity>0 0 -9.8</gravity>
    <magnetic_field>6e-06 2.3e-05 -4.2e-05</magnetic_field>
    <atmosphere type="adiabatic"/>
    <scene>
      <grid>false</grid>
      <ambient>0.4 0.4 0.4 1</ambient>
      <background>0.7 0.7 0.7 1</background>
      <shadows>true</shadows>
    </scene>
    <model name="ground_plane">
      <static>true</static>
      <link name="link">
        <collision name="collision">
          <geometry>
            <plane>
              <normal>0 0 1</normal>
              <size>1 1</size>
            </plane>
          </geometry>
          <surface>
            <friction>
              <ode/>
            </friction>
            <bounce/>
            <contact/>
          </surface>
        </collision>
        <visual name="visual">
          <geometry>
            <plane>
              <normal>0 0 1</normal>
              <size>100 100</size>
            </plane>
          </geometry>
          <material>
            <ambient>0.8 0.8 0.8 1</ambient>
            <diffuse>0.8 0.8 0.8 1</diffuse>
            <specular>0.8 0.8 0.8 1</specular>
          </material>
        </visual>
        <pose>0 0 0 0 -0 0</pose>
        <inertial>
          <pose>0 0 0 0 -0 0</pose>
          <mass>1</mass>
          <inertia>
            <ixx>1</ixx>
            <ixy>0</ixy>
            <ixz>0</ixz>
            <iyy>1</iyy>
            <iyz>0</iyz>
            <izz>1</izz>
          </inertia>
        </inertial>
        <enable_wind>false</enable_wind>
      </link>
      <pose>0 0 0 0 -0 0</pose>
      <self_collide>false</self_collide>
    </model>
    <!-- 四个色块 -->
    <model name="red_pad">
      <static>true</static>
      <link name="link">
        <visual name="visual">
          <geometry>
            <plane>
              <normal>0 0 1</normal>
              <size>1 1</size>
            </plane>
          </geometry>
          <material>
            <ambient>1 0 0 1</ambient>  <!-- 红色 -->
            <diffuse>1 0 0 1</diffuse>
          </material>
        </visual>
      </link>
      <pose>0 3 0.01 0 0 0</pose>  <!-- 前方（Y+方向） -->
    </model>
    <model name="blue_pad">
      <static>true</static>
      <link name="link">
        <visual name="visual">
          <geometry>
            <plane>
              <normal>0 0 1</normal>
              <size>1 1</size>
            </plane>
          </geometry>
          <material>
            <ambient>0 0 1 1</ambient>  <!-- 蓝色 -->
            <diffuse>0 0 1 1</diffuse>
          </material>
        </visual>
      </link>
      <pose>0 -3 0.01 0 0 0</pose>  <!-- 后方（Y-方向） -->
    </model>
    <model name="black_pad">
      <static>true</static>
      <link name="link">
        <visual name="visual">
          <geometry>
            <plane>
              <normal>0 0 1</normal>
              <size>1 1</size>
            </plane>
          </geometry>
          <material>
            <ambient>0.1 0.1 0.1 1</ambient>  <!-- 黑色（避免纯黑） -->
            <diffuse>0.1 0.1 0.1 1</diffuse>
          </material>
        </visual>
      </link>
      <pose>-3 0 0.01 0 0 0</pose>  <!-- 左侧（X-方向） -->
    </model>
    <model name="green_pad">
      <static>true</static>
      <link name="link">
        <visual name="visual">
          <geometry>
            <plane>
              <normal>0 0 1</normal>
              <size>1 1</size>
            </plane>
          </geometry>
          <material>
            <ambient>0 1 0 1</ambient>  <!-- 绿色 -->
            <diffuse>0 1 0 1</diffuse>
          </material>
        </visual>
      </link>
      <pose>3 0 0.01 0 0 0</pose>  <!-- 右侧（X+方向） -->
    </model>

    <!-- teleop_4wd -->
    <model name="teleop_4wd_big">
      <pose>3 0 0 0 0 0</pose>
      <static>false</static>

      <!-- ================= 车体 ================= -->
      <link name="chassis">
        <pose>0 0 1.0 0 0 0</pose> <!-- 原 0.2 × 5 = 1.0 -->
        <inertial>
          <mass>20.0</mass>
          <inertia>
            <ixx>1.0</ixx>
            <iyy>2.0</iyy>
            <izz>2.0</izz>
            <ixy>0</ixy><ixz>0</ixz><iyz>0</iyz>
          </inertia>
        </inertial>
        <collision name="collision">
          <geometry>
            <box><size>3.0 2.0 1.0</size></box> <!-- 0.6 0.4 0.2 × 5 -->
          </geometry>
        </collision>
        <visual name="visual">
          <geometry>
            <box><size>3.0 2.0 1.0</size></box>
          </geometry>
          <material><diffuse>0.3 0.5 0.9 1</diffuse></material>
        </visual>
      </link>

      <!-- ================ 四个轮子（统一放大 5 倍） ================ -->
      <!-- 轮心高度 0.1 × 5 = 0.5 -->

      <!-- 左前轮 -->
      <link name="left_front_wheel">
        <pose>1.25 1.25 0.5 0 0 0</pose> <!-- 0.25 0.25 0.1 × 5 -->
        <collision name="collision">
          <pose>0 0 0 1.5708 0 0</pose>
          <geometry>
            <cylinder>
              <radius>0.5</radius>   <!-- 0.1 × 5 -->
              <length>0.25</length>  <!-- 0.05 × 5 -->
            </cylinder>
          </geometry>
          <surface>
            <friction>
              <ode><mu>2.0</mu><mu2>2.0</mu2></ode>
            </friction>
          </surface>
        </collision>
        <visual name="visual">
          <pose>0 0 0 1.5708 0 0</pose>
          <geometry>
            <cylinder>
              <radius>0.5</radius>
              <length>0.25</length>
            </cylinder>
          </geometry>
          <material><diffuse>0.1 0.1 0.1 1</diffuse></material>
        </visual>
      </link>

      <!-- 左后轮 -->
      <link name="left_rear_wheel">
        <pose>-1.25 1.25 0.5 0 0 0</pose>
        <collision name="collision">
          <pose>0 0 0 1.5708 0 0</pose>
          <geometry>
            <cylinder>
              <radius>0.5</radius>
              <length>0.25</length>
            </cylinder>
          </geometry>
          <surface>
            <friction>
              <ode><mu>2.0</mu><mu2>2.0</mu2></ode>
            </friction>
          </surface>
        </collision>
        <visual name="visual">
          <pose>0 0 0 1.5708 0 0</pose>
          <geometry>
            <cylinder>
              <radius>0.5</radius>
              <length>0.25</length>
            </cylinder>
          </geometry>
          <material><diffuse>0.1 0.1 0.1 1</diffuse></material>
        </visual>
      </link>

      <!-- 右前轮 -->
      <link name="right_front_wheel">
        <pose>1.25 -1.25 0.5 0 0 0</pose>
        <collision name="collision">
          <pose>0 0 0 1.57080 0 0</pose>
          <geometry>
            <cylinder>
              <radius>0.5</radius>
              <length>0.25</length>
            </cylinder>
          </geometry>
          <surface>
            <friction>
              <ode><mu>2.0</mu><mu2>2.0</mu2></ode>
            </friction>
          </surface>
        </collision>
        <visual name="visual">
          <pose>0 0 0 1.5708 0 0</pose>
          <geometry>
            <cylinder>
              <radius>0.5</radius>
              <length>0.25</length>
            </cylinder>
          </geometry>
          <material><diffuse>0.1 0.1 0.1 1</diffuse></material>
        </visual>
      </link>

      <!-- 右后轮 -->
      <link name="right_rear_wheel">
        <pose>-1.25 -1.25 0.5 0 0 0</pose>
        <collision name="collision">
          <pose>0 0 0 1.5708 0 0</pose>
          <geometry>
            <cylinder>
              <radius>0.5</radius>
              <length>0.25</length>
            </cylinder>
          </geometry>
          <surface>
            <friction>
              <ode><mu>2.0</mu><mu2>2.0</mu2></ode>
            </friction>
          </surface>
        </collision>
        <visual name="visual">
          <pose>0 0 0 1.5708 0 0</pose>
          <geometry>
            <cylinder>
              <radius>0.5</radius>
              <length>0.25</length>
            </cylinder>
          </geometry>
          <material><diffuse>0.1 0.1 0.1 1</diffuse></material>
        </visual>
      </link>

      <!-- ======================= 四个关节 ======================= -->

      <joint name="left_front_joint" type="revolute">
        <parent>chassis</parent>
        <child>left_front_wheel</child>
        <axis><xyz>0 1 0</xyz></axis>
      </joint>

      <joint name="left_rear_joint" type="revolute">
        <parent>chassis</parent>
        <child>left_rear_wheel</child>
        <axis><xyz>0 1 0</xyz></axis>
      </joint>

      <joint name="right_front_joint" type="revolute">
        <parent>chassis</parent>
        <child>right_front_wheel</child>
        <axis><xyz>0 1 0</xyz></axis>
      </joint>

      <joint name="right_rear_joint" type="revolute">
        <parent>chassis</parent>
        <child>right_rear_wheel</child>
        <axis><xyz>0 1 0</xyz></axis>
      </joint>

      <!-- ======================= 四驱插件 ======================= -->
      <plugin filename="gz-sim-diff-drive-system"
              name="gz::sim::systems::DiffDrive">

        <left_joint>left_front_joint</left_joint>
        <left_joint>left_rear_joint</left_joint>

        <right_joint>right_front_joint</right_joint>
        <right_joint>right_rear_joint</right_joint>

        <wheel_separation>2.5</wheel_separation>  <!-- 0.50 × 5 -->
        <wheel_radius>0.5</wheel_radius>          <!-- 0.10 × 5 -->

        <max_linear_velocity>1.0</max_linear_velocity>
        <max_angular_velocity>1.0</max_angular_velocity>
        <max_acceleration>1.0</max_acceleration>
        <max_deceleration>1.0</max_deceleration>

        <topic>/cmd_vel</topic>
      </plugin>

    </model>


    <light name="sunUTC" type="directional">
      <pose>0 0 500 0 -0 0</pose>
      <cast_shadows>true</cast_shadows>
      <intensity>1</intensity>
      <direction>0.001 0.625 -0.78</direction>
      <diffuse>0.904 0.904 0.904 1</diffuse>
      <specular>0.271 0.271 0.271 1</specular>
      <attenuation>
        <range>2000</range>
        <linear>0</linear>
        <constant>1</constant>
        <quadratic>0</quadratic>
      </attenuation>
      <spot>
        <inner_angle>0</inner_angle>
        <outer_angle>0</outer_angle>
        <falloff>0</falloff>
      </spot>
    </light>
    <spherical_coordinates>
      <surface_model>EARTH_WGS84</surface_model>
      <world_frame_orientation>ENU</world_frame_orientation>
      <latitude_deg>47.397971057728974</latitude_deg>
      <longitude_deg> 8.546163739800146</longitude_deg>
      <elevation>0</elevation>
    </spherical_coordinates>
  </world>
</sdf>
